Workbook

Sheet Schedule
A1: HSF Social Communication — 48 Core Post Cycle Tracker | 01 September–27 October 2026
A2: Historical records (01–06 Sep) are preserved as published. From 07 Sep: Mon–Tue Education | Wed–Thu Health | Friday Off | Sat–Sun Climate. Morning overlays remain opportunity-led; P01–P48 headings stay locked.
A4: Calendar # | B4: Date | C4: Day | D4: Week | E4: Programme / Lens | F4: 2-Day Block | G4: Morning Window | H4: Morning ID | I4: Category | J4: Morning Post / Direction | K4: Morning Status | L4: Morning URL | M4: Afternoon Window | N4: Afternoon Stream | O4: Afternoon ID | P4: Issue / Resolution | Q4: Afternoon Heading / Post | R4: Format | S4: Afternoon Status | T4: Afternoon URL | U4: Overall Status | V4: Evidence / Safeguarding Check | W4: Notes
A5: 1 | B5: 46266 | C5: Tuesday | D5: Week 1 | E5: E4BL – Education | F5: Historical | G5: 9:00–10:00 AM | H5: FIELD-001 | I5: FIELD | J5: Hazaribagh Center students received learning materials to support classroom activities. | K5: Published | M5: 4:00–5:00 PM | N5: Core | O5: P01 | P5: Issue | Q5: When Money Becomes a Barrier to Learning | R5: Standard | S5: Published | U5: =IF(C5="Friday","Friday Off",IF(AND(K5="Published",S5="Published"),"Both Published",IF(OR(K5="Needs Reschedule",S5="Needs Reschedule"),"Needs Reschedule",IF(OR(K5="Published",S5="Published"),"Partially Published",IF(AND(K5="Scheduled",S5="Scheduled"),"Scheduled","Planned"))))) -> Both Published | V5: Published activity supplied by user; photographs available. Protect children’s privacy; no names, registers or personal details visible. | W5: Historical published record.
A6: 2 | B6: 46267 | C6: Wednesday | D6: Week 1 | E6: E4BL – Education | F6: Historical | G6: 9:00–10:00 AM | H6: MOMENT-001 | I6: MOMENT | J6: Putting the new learning materials to use — students using the materials in ordinary classwork. | K6: Published | M6: 4:00–5:00 PM | N6: Core | O6: P02 | P6: Resolution | Q6: How Learning Can Continue When Resources Are Limited | R6: Standard | S6: Published | U6: =IF(C6="Friday","Friday Off",IF(AND(K6="Published",S6="Published"),"Both Published",IF(OR(K6="Needs Reschedule",S6="Needs Reschedule"),"Needs Reschedule",IF(OR(K6="Published",S6="Published"),"Partially Published",IF(AND(K6="Scheduled",S6="Scheduled"),"Scheduled","Planned"))))) -> Both Published | V6: Use only the observed classroom activity; do not claim improved academic performance from material use. | W6: Historical published record.
A7: 3 | B7: 46268 | C7: Thursday | D7: Week 1 | E7: Mixed – Historical | F7: Historical exception | G7: 9:00–10:00 AM | H7: FIELD-003 | I7: FIELD | J7: Before a medical camp begins — team setup, consultation space and preparation. | K7: Published | M7: 4:00–5:00 PM | N7: Overlay | O7: MOMENT-002 | P7: MOMENT | Q7: Weekly Cultural / Sports Event — E4BL Uttara Center | R7: Photo / Moment | S7: Published | U7: =IF(C7="Friday","Friday Off",IF(AND(K7="Published",S7="Published"),"Both Published",IF(OR(K7="Needs Reschedule",S7="Needs Reschedule"),"Needs Reschedule",IF(OR(K7="Published",S7="Published"),"Partially Published",IF(AND(K7="Scheduled",S7="Scheduled"),"Scheduled","Planned"))))) -> Both Published | V7: Morning: use only verified camp-preparation details and protect patient privacy. Afternoon: weekly E4BL cultural/sports activity was published as an overlay, not a P01–P48 core post. | W7: Pre-new-rhythm historical exception; both posts published.
A8: 4 | B8: 46269 | C8: Friday | D8: Week 1 | E8: — | F8: Friday Off | G8: — | H8: — | I8: — | J8: No post | K8: Friday Off | M8: — | N8: — | O8: — | P8: — | Q8: No post | R8: — | S8: Friday Off | U8: =IF(C8="Friday","Friday Off",IF(AND(K8="Published",S8="Published"),"Both Published",IF(OR(K8="Needs Reschedule",S8="Needs Reschedule"),"Needs Reschedule",IF(OR(K8="Published",S8="Published"),"Partially Published",IF(AND(K8="Scheduled",S8="Scheduled"),"Scheduled","Planned"))))) -> Friday Off | V8: No posting on Friday. | W8: Planned weekly pause.
A9: 5 | B9: 46270 | C9: Saturday | D9: Week 1 | E9: A2PHC – Health | F9: Historical | G9: 9:00–10:00 AM | H9: MOMENT-003 | I9: MOMENT | J9: A doctor listening — respectful consultation environment showing human interaction. | K9: Published | M9: 4:00–5:00 PM | N9: Core | O9: P13 | P9: Issue | Q9: Waiting Too Long Can Make a Manageable Health Concern Harder | R9: Standard | S9: Published | U9: =IF(C9="Friday","Friday Off",IF(AND(K9="Published",S9="Published"),"Both Published",IF(OR(K9="Needs Reschedule",S9="Needs Reschedule"),"Needs Reschedule",IF(OR(K9="Published",S9="Published"),"Partially Published",IF(AND(K9="Scheduled",S9="Scheduled"),"Scheduled","Planned"))))) -> Both Published | V9: Describe consultation and respectful interaction only; do not imply diagnosis, successful treatment or recovery. | W9: Historical published record.
A10: 6 | B10: 46271 | C10: Sunday | D10: Week 1 | E10: A2PHC – Health | F10: Historical | G10: 9:00–10:00 AM | H10: FIELD-006 | I10: FIELD | J10: Primary healthcare closer to the community — actual camp location and consultation setting. | K10: Published | M10: 4:00–5:00 PM | N10: Core | O10: P14 | P10: Resolution | Q10: Primary Care Can Help People Seek the Right Next Step Earlier | R10: Standard | S10: Published | U10: =IF(C10="Friday","Friday Off",IF(AND(K10="Published",S10="Published"),"Both Published",IF(OR(K10="Needs Reschedule",S10="Needs Reschedule"),"Needs Reschedule",IF(OR(K10="Published",S10="Published"),"Partially Published",IF(AND(K10="Scheduled",S10="Scheduled"),"Scheduled","Planned"))))) -> Both Published | V10: No patient information, prescriptions, registers or identifiable clinical details in frame. | W10: User confirmed both posts published on 06-Sep-2026.
A11: 7 | B11: 46272 | C11: Monday | D11: Week 1 | E11: E4BL – Education | F11: Block 01 – Day 1 | G11: 9:00–10:00 AM | H11: FIELD-007 | I11: FIELD | J11: Assembly before a regular school day — an authentic E4BL school routine. | K11: Scheduled | M11: 4:00–5:00 PM | N11: Core | O11: P03 | P11: Issue | Q11: School Dropout Usually Starts Before the Last Day in Class | R11: Standard | S11: Scheduled | U11: =IF(C11="Friday","Friday Off",IF(AND(K11="Published",S11="Published"),"Both Published",IF(OR(K11="Needs Reschedule",S11="Needs Reschedule"),"Needs Reschedule",IF(OR(K11="Published",S11="Published"),"Partially Published",IF(AND(K11="Scheduled",S11="Scheduled"),"Scheduled","Planned"))))) -> Scheduled | V11: Use current verified E4BL activity evidence. Protect children’s dignity and privacy; no unnecessary names, registers or personal details. Do not infer learning outcomes. | W11: Existing scheduled date retained under the revised programme rhythm.
A12: 8 | B12: 46273 | C12: Tuesday | D12: Week 2 | E12: E4BL – Education | F12: Block 01 – Day 2 | G12: 9:00–10:00 AM | H12: OBS-001 | I12: OBS | J12: International Literacy Day — connect literacy with everyday learning and education continuity. | K12: Scheduled | M12: 4:00–5:00 PM | N12: Core | O12: P04 | P12: Resolution | Q12: Notice the Signs Before Learning Stops | R12: Special Engagement | S12: Scheduled | U12: =IF(C12="Friday","Friday Off",IF(AND(K12="Published",S12="Published"),"Both Published",IF(OR(K12="Needs Reschedule",S12="Needs Reschedule"),"Needs Reschedule",IF(OR(K12="Published",S12="Published"),"Partially Published",IF(AND(K12="Scheduled",S12="Scheduled"),"Scheduled","Planned"))))) -> Scheduled | V12: Use current verified E4BL activity evidence. Protect children’s dignity and privacy; no unnecessary names, registers or personal details. Do not infer learning outcomes. | W12: Existing scheduled date retained under the revised programme rhythm.
A13: 9 | B13: 46274 | C13: Wednesday | D13: Week 2 | E13: A2PHC – Health | F13: Block 02 – Day 1 | G13: 9:00–10:00 AM | H13: FIELD-008 | I13: FIELD | J13: Community health awareness in simple language — use a real A2PHC session or field interaction. | K13: Needs Reschedule | M13: 4:00–5:00 PM | N13: Core | O13: P15 | P13: Issue | Q13: Health Information Is Everywhere, but Not All of It Is Reliable | R13: Standard | S13: Scheduled | U13: =IF(C13="Friday","Friday Off",IF(AND(K13="Published",S13="Published"),"Both Published",IF(OR(K13="Needs Reschedule",S13="Needs Reschedule"),"Needs Reschedule",IF(OR(K13="Published",S13="Published"),"Partially Published",IF(AND(K13="Scheduled",S13="Scheduled"),"Scheduled","Planned"))))) -> Needs Reschedule | V13: Use current verified A2PHC activity evidence. Protect patient privacy; no prescriptions, registers, diagnoses linked to people or unsupported clinical outcome claims. | W13: Morning content changed to Health to keep one programme all day; replace the previously scheduled Education morning post. Afternoon core remains scheduled.
A14: 10 | B14: 46275 | C14: Thursday | D14: Week 2 | E14: A2PHC – Health | F14: Block 02 – Day 2 | G14: 9:00–10:00 AM | H14: MOMENT-004 | I14: MOMENT | J14: One health message explained clearly — staff using a poster, flipchart or conversation. | K14: Needs Reschedule | M14: 4:00–5:00 PM | N14: Core | O14: P16 | P14: Resolution | Q14: Simple Preventive Habits Work Best When the Advice Is Verified | R14: Special Engagement | S14: Scheduled | U14: =IF(C14="Friday","Friday Off",IF(AND(K14="Published",S14="Published"),"Both Published",IF(OR(K14="Needs Reschedule",S14="Needs Reschedule"),"Needs Reschedule",IF(OR(K14="Published",S14="Published"),"Partially Published",IF(AND(K14="Scheduled",S14="Scheduled"),"Scheduled","Planned"))))) -> Needs Reschedule | V14: Use current verified A2PHC activity evidence. Protect patient privacy; no prescriptions, registers, diagnoses linked to people or unsupported clinical outcome claims. | W14: Morning content changed to Health to keep one programme all day; replace the previously scheduled Education morning post. Afternoon core remains scheduled.
A15: 11 | B15: 46276 | C15: Friday | D15: Week 2 | E15: — | F15: Friday Off | G15: — | H15: — | I15: — | J15: No post | K15: Friday Off | M15: — | N15: — | O15: — | P15: — | Q15: No post | R15: — | S15: Friday Off | U15: =IF(C15="Friday","Friday Off",IF(AND(K15="Published",S15="Published"),"Both Published",IF(OR(K15="Needs Reschedule",S15="Needs Reschedule"),"Needs Reschedule",IF(OR(K15="Published",S15="Published"),"Partially Published",IF(AND(K15="Scheduled",S15="Scheduled"),"Scheduled","Planned"))))) -> Friday Off | V15: No posting on Friday. | W15: Planned weekly pause.
A16: 12 | B16: 46277 | C16: Saturday | D16: Week 2 | E16: Climate Action | F16: Block 03 – Day 1 | G16: 9:00–10:00 AM | H16: FIELD-009 | I16: FIELD | J16: Youth climate discussion on heat, changing weather or everyday climate risk. | K16: Planned | M16: 4:00–5:00 PM | N16: Core | O16: P23 | P16: Issue | Q16: Extreme Heat Is More Than Discomfort | R16: Standard | S16: Planned | U16: =IF(C16="Friday","Friday Off",IF(AND(K16="Published",S16="Published"),"Both Published",IF(OR(K16="Needs Reschedule",S16="Needs Reschedule"),"Needs Reschedule",IF(OR(K16="Published",S16="Published"),"Partially Published",IF(AND(K16="Scheduled",S16="Scheduled"),"Scheduled","Planned"))))) -> Planned | V16: Use current verified Climate Action evidence. Do not invent beneficiary totals, programme activities or impact claims; keep statements proportional to documented activity.
A17: 13 | B17: 46278 | C17: Sunday | D17: Week 2 | E17: Climate Action | F17: Block 03 – Day 2 | G17: 9:00–10:00 AM | H17: MOMENT-005 | I17: MOMENT | J17: A practical heat-safety moment — shade, water, rest or safer daily-space choices. | K17: Planned | M17: 4:00–5:00 PM | N17: Core | O17: P24 | P17: Resolution | Q17: Low-Cost Heat Actions Can Make Daily Spaces Safer | R17: Special Engagement | S17: Planned | U17: =IF(C17="Friday","Friday Off",IF(AND(K17="Published",S17="Published"),"Both Published",IF(OR(K17="Needs Reschedule",S17="Needs Reschedule"),"Needs Reschedule",IF(OR(K17="Published",S17="Published"),"Partially Published",IF(AND(K17="Scheduled",S17="Scheduled"),"Scheduled","Planned"))))) -> Planned | V17: Use current verified Climate Action evidence. Do not invent beneficiary totals, programme activities or impact claims; keep statements proportional to documented activity.
A18: 14 | B18: 46279 | C18: Monday | D18: Week 2 | E18: E4BL – Education | F18: Block 04 – Day 1 | G18: 9:00–10:00 AM | H18: MOMENT-006 | I18: MOMENT | J18: Learning with simple materials — ordinary classwork using what is already available. | K18: Planned | M18: 4:00–5:00 PM | N18: Core | O18: P05 | P18: Issue | Q18: Learning Should Not Depend on Expensive Materials | R18: Standard | S18: Planned | U18: =IF(C18="Friday","Friday Off",IF(AND(K18="Published",S18="Published"),"Both Published",IF(OR(K18="Needs Reschedule",S18="Needs Reschedule"),"Needs Reschedule",IF(OR(K18="Published",S18="Published"),"Partially Published",IF(AND(K18="Scheduled",S18="Scheduled"),"Scheduled","Planned"))))) -> Planned | V18: Use current verified E4BL activity evidence. Protect children’s dignity and privacy; no unnecessary names, registers or personal details. Do not infer learning outcomes.
A19: 15 | B19: 46280 | C19: Tuesday | D19: Week 3 | E19: E4BL – Education | F19: Block 04 – Day 2 | G19: 9:00–10:00 AM | H19: FIELD-010 | I19: FIELD | J19: A regular classroom morning — reading, writing and guided classwork at Hazaribagh or Uttara. | K19: Planned | M19: 4:00–5:00 PM | N19: Core | O19: P06 | P19: Resolution | Q19: A Simple Learning Routine Can Start With What Is Already Available | R19: Standard | S19: Planned | U19: =IF(C19="Friday","Friday Off",IF(AND(K19="Published",S19="Published"),"Both Published",IF(OR(K19="Needs Reschedule",S19="Needs Reschedule"),"Needs Reschedule",IF(OR(K19="Published",S19="Published"),"Partially Published",IF(AND(K19="Scheduled",S19="Scheduled"),"Scheduled","Planned"))))) -> Planned | V19: Use current verified E4BL activity evidence. Protect children’s dignity and privacy; no unnecessary names, registers or personal details. Do not infer learning outcomes.
A20: 16 | B20: 46281 | C20: Wednesday | D20: Week 3 | E20: A2PHC – Health | F20: Block 05 – Day 1 | G20: 9:00–10:00 AM | H20: FIELD-011 | I20: FIELD | J20: Routine primary-care consultation or check environment, if verified and safe to show. | K20: Planned | M20: 4:00–5:00 PM | N20: Core | O20: P17 | P20: Issue | Q20: Some Health Risks Do Not Announce Themselves Early | R20: Standard | S20: Planned | U20: =IF(C20="Friday","Friday Off",IF(AND(K20="Published",S20="Published"),"Both Published",IF(OR(K20="Needs Reschedule",S20="Needs Reschedule"),"Needs Reschedule",IF(OR(K20="Published",S20="Published"),"Partially Published",IF(AND(K20="Scheduled",S20="Scheduled"),"Scheduled","Planned"))))) -> Planned | V20: Use current verified A2PHC activity evidence. Protect patient privacy; no prescriptions, registers, diagnoses linked to people or unsupported clinical outcome claims.
A21: 17 | B21: 46282 | C21: Thursday | D21: Week 3 | E21: A2PHC – Health | F21: Block 05 – Day 2 | G21: 9:00–10:00 AM | H21: MOMENT-007 | I21: MOMENT | J21: Listening is part of good healthcare — a dignified doctor/community interaction. | K21: Planned | M21: 4:00–5:00 PM | N21: Core | O21: P18 | P21: Resolution | Q21: Routine Checks Can Support Earlier Professional Attention | R21: Standard | S21: Planned | U21: =IF(C21="Friday","Friday Off",IF(AND(K21="Published",S21="Published"),"Both Published",IF(OR(K21="Needs Reschedule",S21="Needs Reschedule"),"Needs Reschedule",IF(OR(K21="Published",S21="Published"),"Partially Published",IF(AND(K21="Scheduled",S21="Scheduled"),"Scheduled","Planned"))))) -> Planned | V21: Use current verified A2PHC activity evidence. Protect patient privacy; no prescriptions, registers, diagnoses linked to people or unsupported clinical outcome claims.
A22: 18 | B22: 46283 | C22: Friday | D22: Week 3 | E22: — | F22: Friday Off | G22: — | H22: — | I22: — | J22: No post | K22: Friday Off | M22: — | N22: — | O22: — | P22: — | Q22: No post | R22: — | S22: Friday Off | U22: =IF(C22="Friday","Friday Off",IF(AND(K22="Published",S22="Published"),"Both Published",IF(OR(K22="Needs Reschedule",S22="Needs Reschedule"),"Needs Reschedule",IF(OR(K22="Published",S22="Published"),"Partially Published",IF(AND(K22="Scheduled",S22="Scheduled"),"Scheduled","Planned"))))) -> Friday Off | V22: No posting on Friday. | W22: Planned weekly pause.
A23: 19 | B23: 46284 | C23: Saturday | D23: Week 3 | E23: Climate Action | F23: Block 06 – Day 1 | G23: 9:00–10:00 AM | H23: FIELD-012 | I23: FIELD | J23: Community discussion on heavy rain, flood risk or locally relevant preparedness. | K23: Planned | M23: 4:00–5:00 PM | N23: Core | O23: P25 | P23: Issue | Q23: Heavy Rain Becomes More Dangerous When Preparation Starts Too Late | R23: Standard | S23: Planned | U23: =IF(C23="Friday","Friday Off",IF(AND(K23="Published",S23="Published"),"Both Published",IF(OR(K23="Needs Reschedule",S23="Needs Reschedule"),"Needs Reschedule",IF(OR(K23="Published",S23="Published"),"Partially Published",IF(AND(K23="Scheduled",S23="Scheduled"),"Scheduled","Planned"))))) -> Planned | V23: Use current verified Climate Action evidence. Do not invent beneficiary totals, programme activities or impact claims; keep statements proportional to documented activity.
A24: 20 | B24: 46285 | C24: Sunday | D24: Week 3 | E24: Climate Action | F24: Block 06 – Day 2 | G24: 9:00–10:00 AM | H24: MOMENT-008 | I24: MOMENT | J24: A household-readiness discussion or practical preparedness moment. | K24: Planned | M24: 4:00–5:00 PM | N24: Core | O24: P26 | P24: Resolution | Q24: A Simple Household Readiness Plan Can Reduce Avoidable Risk | R24: Standard | S24: Planned | U24: =IF(C24="Friday","Friday Off",IF(AND(K24="Published",S24="Published"),"Both Published",IF(OR(K24="Needs Reschedule",S24="Needs Reschedule"),"Needs Reschedule",IF(OR(K24="Published",S24="Published"),"Partially Published",IF(AND(K24="Scheduled",S24="Scheduled"),"Scheduled","Planned"))))) -> Planned | V24: Use current verified Climate Action evidence. Do not invent beneficiary totals, programme activities or impact claims; keep statements proportional to documented activity.
A25: 21 | B25: 46286 | C25: Monday | D25: Week 3 | E25: E4BL – Education | F25: Block 07 – Day 1 | G25: 9:00–10:00 AM | H25: FIELD-013 | I25: FIELD | J25: Guardian–school communication — guardian meeting or teacher-parent discussion. | K25: Planned | M25: 4:00–5:00 PM | N25: Core | O25: P07 | P25: Issue | Q25: A Child Struggles More When Home and School Work Separately | R25: Standard | S25: Planned | U25: =IF(C25="Friday","Friday Off",IF(AND(K25="Published",S25="Published"),"Both Published",IF(OR(K25="Needs Reschedule",S25="Needs Reschedule"),"Needs Reschedule",IF(OR(K25="Published",S25="Published"),"Partially Published",IF(AND(K25="Scheduled",S25="Scheduled"),"Scheduled","Planned"))))) -> Planned | V25: Use current verified E4BL activity evidence. Protect children’s dignity and privacy; no unnecessary names, registers or personal details. Do not infer learning outcomes.
A26: 22 | B26: 46287 | C26: Tuesday | D26: Week 4 | E26: E4BL – Education | F26: Block 07 – Day 2 | G26: 9:00–10:00 AM | H26: MOMENT-009 | I26: MOMENT | J26: One teacher–guardian conversation focused on supporting a learner. | K26: Planned | M26: 4:00–5:00 PM | N26: Core | O26: P08 | P26: Resolution | Q26: One Small Teacher–Guardian Conversation Can Make Support Clearer | R26: Special Engagement | S26: Planned | U26: =IF(C26="Friday","Friday Off",IF(AND(K26="Published",S26="Published"),"Both Published",IF(OR(K26="Needs Reschedule",S26="Needs Reschedule"),"Needs Reschedule",IF(OR(K26="Published",S26="Published"),"Partially Published",IF(AND(K26="Scheduled",S26="Scheduled"),"Scheduled","Planned"))))) -> Planned | V26: Use current verified E4BL activity evidence. Protect children’s dignity and privacy; no unnecessary names, registers or personal details. Do not infer learning outcomes.
A27: 23 | B27: 46288 | C27: Wednesday | D27: Week 4 | E27: A2PHC – Health | F27: Block 08 – Day 1 | G27: 9:00–10:00 AM | H27: FIELD-014 | I27: FIELD | J27: Community hygiene awareness — safe water, food hygiene, sanitation or handwashing where actually discussed. | K27: Planned | M27: 4:00–5:00 PM | N27: Core | O27: P19 | P27: Issue | Q27: Small Hygiene Gaps Can Create Bigger Health Risks | R27: Standard | S27: Planned | U27: =IF(C27="Friday","Friday Off",IF(AND(K27="Published",S27="Published"),"Both Published",IF(OR(K27="Needs Reschedule",S27="Needs Reschedule"),"Needs Reschedule",IF(OR(K27="Published",S27="Published"),"Partially Published",IF(AND(K27="Scheduled",S27="Scheduled"),"Scheduled","Planned"))))) -> Planned | V27: Use current verified A2PHC activity evidence. Protect patient privacy; no prescriptions, registers, diagnoses linked to people or unsupported clinical outcome claims.
A28: 24 | B28: 46289 | C28: Thursday | D28: Week 4 | E28: A2PHC – Health | F28: Block 08 – Day 2 | G28: 9:00–10:00 AM | H28: MOMENT-010 | I28: MOMENT | J28: A simple hygiene practice explained or demonstrated in a community setting. | K28: Planned | M28: 4:00–5:00 PM | N28: Core | O28: P20 | P28: Resolution | Q28: A Household Hygiene Checklist Can Turn Awareness Into Routine | R28: Special Engagement | S28: Planned | U28: =IF(C28="Friday","Friday Off",IF(AND(K28="Published",S28="Published"),"Both Published",IF(OR(K28="Needs Reschedule",S28="Needs Reschedule"),"Needs Reschedule",IF(OR(K28="Published",S28="Published"),"Partially Published",IF(AND(K28="Scheduled",S28="Scheduled"),"Scheduled","Planned"))))) -> Planned | V28: Use current verified A2PHC activity evidence. Protect patient privacy; no prescriptions, registers, diagnoses linked to people or unsupported clinical outcome claims.
A29: 25 | B29: 46290 | C29: Friday | D29: Week 4 | E29: — | F29: Friday Off | G29: — | H29: — | I29: — | J29: No post | K29: Friday Off | M29: — | N29: — | O29: — | P29: — | Q29: No post | R29: — | S29: Friday Off | U29: =IF(C29="Friday","Friday Off",IF(AND(K29="Published",S29="Published"),"Both Published",IF(OR(K29="Needs Reschedule",S29="Needs Reschedule"),"Needs Reschedule",IF(OR(K29="Published",S29="Published"),"Partially Published",IF(AND(K29="Scheduled",S29="Scheduled"),"Scheduled","Planned"))))) -> Friday Off | V29: No posting on Friday. | W29: Planned weekly pause.
A30: 26 | B30: 46291 | C30: Saturday | D30: Week 4 | E30: Climate Action | F30: Block 09 – Day 1 | G30: 9:00–10:00 AM | H30: FIELD-015 | I30: FIELD | J30: Environmental cleanliness or plastic-awareness activity where verified. | K30: Planned | M30: 4:00–5:00 PM | N30: Core | O30: P27 | P30: Issue | Q30: Single-Use Plastic Leaves a Longer Problem Than Its Short Use | R30: Standard | S30: Planned | U30: =IF(C30="Friday","Friday Off",IF(AND(K30="Published",S30="Published"),"Both Published",IF(OR(K30="Needs Reschedule",S30="Needs Reschedule"),"Needs Reschedule",IF(OR(K30="Published",S30="Published"),"Partially Published",IF(AND(K30="Scheduled",S30="Scheduled"),"Scheduled","Planned"))))) -> Planned | V30: Use current verified Climate Action evidence. Do not invent beneficiary totals, programme activities or impact claims; keep statements proportional to documented activity.
A31: 27 | B31: 46292 | C31: Sunday | D31: Week 4 | E31: Climate Action | F31: Block 09 – Day 2 | G31: 9:00–10:00 AM | H31: MOMENT-011 | I31: MOMENT | J31: One practical local environmental action — waste reduction or cleaner surroundings. | K31: Planned | M31: 4:00–5:00 PM | N31: Core | O31: P28 | P31: Resolution | Q31: Plastic Reduction Works Better as a Practical Habit Than a Slogan | R31: Special Engagement | S31: Planned | U31: =IF(C31="Friday","Friday Off",IF(AND(K31="Published",S31="Published"),"Both Published",IF(OR(K31="Needs Reschedule",S31="Needs Reschedule"),"Needs Reschedule",IF(OR(K31="Published",S31="Published"),"Partially Published",IF(AND(K31="Scheduled",S31="Scheduled"),"Scheduled","Planned"))))) -> Planned | V31: Use current verified Climate Action evidence. Do not invent beneficiary totals, programme activities or impact claims; keep statements proportional to documented activity.
A32: 28 | B32: 46293 | C32: Monday | D32: Week 4 | E32: E4BL – Education | F32: Block 10 – Day 1 | G32: 9:00–10:00 AM | H32: FIELD-016 | I32: FIELD | J32: Regular classroom participation — children staying connected to learning through ordinary school activity. | K32: Planned | M32: 4:00–5:00 PM | N32: Core | O32: P09 | P32: Issue | Q32: A Small Income Today Can Carry a Long Educational Cost | R32: Standard | S32: Planned | U32: =IF(C32="Friday","Friday Off",IF(AND(K32="Published",S32="Published"),"Both Published",IF(OR(K32="Needs Reschedule",S32="Needs Reschedule"),"Needs Reschedule",IF(OR(K32="Published",S32="Published"),"Partially Published",IF(AND(K32="Scheduled",S32="Scheduled"),"Scheduled","Planned"))))) -> Planned | V32: Use current verified E4BL activity evidence. Protect children’s dignity and privacy; no unnecessary names, registers or personal details. Do not infer learning outcomes.
A33: 29 | B33: 46294 | C33: Tuesday | D33: Week 5 | E33: E4BL – Education | F33: Block 10 – Day 2 | G33: 9:00–10:00 AM | H33: MOMENT-012 | I33: MOMENT | J33: Teacher or classroom support that helps children remain engaged with learning. | K33: Planned | M33: 4:00–5:00 PM | N33: Core | O33: P10 | P33: Resolution | Q33: What Can Help a Child Stay Connected to Learning | R33: Standard | S33: Planned | U33: =IF(C33="Friday","Friday Off",IF(AND(K33="Published",S33="Published"),"Both Published",IF(OR(K33="Needs Reschedule",S33="Needs Reschedule"),"Needs Reschedule",IF(OR(K33="Published",S33="Published"),"Partially Published",IF(AND(K33="Scheduled",S33="Scheduled"),"Scheduled","Planned"))))) -> Planned | V33: Use current verified E4BL activity evidence. Protect children’s dignity and privacy; no unnecessary names, registers or personal details. Do not infer learning outcomes.
A34: 30 | B34: 46295 | C34: Wednesday | D34: Week 5 | E34: A2PHC – Health | F34: Block 11 – Day 1 | G34: 9:00–10:00 AM | H34: FIELD-017 | I34: FIELD | J34: Women’s or girls’ health / menstrual-hygiene education only where an approved real session occurs. | K34: Planned | M34: 4:00–5:00 PM | N34: Core | O34: P21 | P34: Issue | Q34: Shame and Misinformation Can Become Health and Education Barriers | R34: Standard | S34: Planned | U34: =IF(C34="Friday","Friday Off",IF(AND(K34="Published",S34="Published"),"Both Published",IF(OR(K34="Needs Reschedule",S34="Needs Reschedule"),"Needs Reschedule",IF(OR(K34="Published",S34="Published"),"Partially Published",IF(AND(K34="Scheduled",S34="Scheduled"),"Scheduled","Planned"))))) -> Planned | V34: Use current verified A2PHC activity evidence. Protect patient privacy; no prescriptions, registers, diagnoses linked to people or unsupported clinical outcome claims.
A35: 31 | B35: 46296 | C35: Thursday | D35: Week 5 | E35: A2PHC – Health | F35: Block 11 – Day 2 | G35: 9:00–10:00 AM | H35: MOMENT-013 | I35: MOMENT | J35: Practical, private and respectful menstrual-hygiene information in an approved setting. | K35: Planned | M35: 4:00–5:00 PM | N35: Core | O35: P22 | P35: Resolution | Q35: Menstrual Hygiene Information Should Be Practical, Private and Respectful | R35: Standard | S35: Planned | U35: =IF(C35="Friday","Friday Off",IF(AND(K35="Published",S35="Published"),"Both Published",IF(OR(K35="Needs Reschedule",S35="Needs Reschedule"),"Needs Reschedule",IF(OR(K35="Published",S35="Published"),"Partially Published",IF(AND(K35="Scheduled",S35="Scheduled"),"Scheduled","Planned"))))) -> Planned | V35: Use current verified A2PHC activity evidence. Protect patient privacy; no prescriptions, registers, diagnoses linked to people or unsupported clinical outcome claims.
A36: 32 | B36: 46297 | C36: Friday | D36: Week 5 | E36: — | F36: Friday Off | G36: — | H36: — | I36: — | J36: No post | K36: Friday Off | M36: — | N36: — | O36: — | P36: — | Q36: No post | R36: — | S36: Friday Off | U36: =IF(C36="Friday","Friday Off",IF(AND(K36="Published",S36="Published"),"Both Published",IF(OR(K36="Needs Reschedule",S36="Needs Reschedule"),"Needs Reschedule",IF(OR(K36="Published",S36="Published"),"Partially Published",IF(AND(K36="Scheduled",S36="Scheduled"),"Scheduled","Planned"))))) -> Friday Off | V36: No posting on Friday. | W36: Planned weekly pause.
A37: 33 | B37: 46298 | C37: Saturday | D37: Week 5 | E37: Climate Action | F37: Block 12 – Day 1 | G37: 9:00–10:00 AM | H37: FIELD-018 | I37: FIELD | J37: Tree care, shade or local environmental conditions as a verified Climate Action activity. | K37: Planned | M37: 4:00–5:00 PM | N37: Core | O37: P29 | P37: Issue | Q37: Hotter, Harder Spaces Are Often Shaped by the Environment Around Us | R37: Standard | S37: Planned | U37: =IF(C37="Friday","Friday Off",IF(AND(K37="Published",S37="Published"),"Both Published",IF(OR(K37="Needs Reschedule",S37="Needs Reschedule"),"Needs Reschedule",IF(OR(K37="Published",S37="Published"),"Partially Published",IF(AND(K37="Scheduled",S37="Scheduled"),"Scheduled","Planned"))))) -> Planned | V37: Use current verified Climate Action evidence. Do not invent beneficiary totals, programme activities or impact claims; keep statements proportional to documented activity.
A38: 34 | B38: 46299 | C38: Sunday | D38: Week 5 | E38: Climate Action | F38: Block 12 – Day 2 | G38: 9:00–10:00 AM | H38: MOMENT-014 | I38: MOMENT | J38: One local resilience choice — shade, tree care, water or community environmental action. | K38: Planned | M38: 4:00–5:00 PM | N38: Core | O38: P30 | P38: Resolution | Q38: Small Local Design Choices Can Improve Shade, Comfort and Resilience | R38: Standard | S38: Planned | U38: =IF(C38="Friday","Friday Off",IF(AND(K38="Published",S38="Published"),"Both Published",IF(OR(K38="Needs Reschedule",S38="Needs Reschedule"),"Needs Reschedule",IF(OR(K38="Published",S38="Published"),"Partially Published",IF(AND(K38="Scheduled",S38="Scheduled"),"Scheduled","Planned"))))) -> Planned | V38: Use current verified Climate Action evidence. Do not invent beneficiary totals, programme activities or impact claims; keep statements proportional to documented activity.
A39: 35 | B39: 46300 | C39: Monday | D39: Week 5 | E39: E4BL – Education | F39: Block 13 – Day 1 | G39: 9:00–10:00 AM | H39: OBS-002 | I39: OBS | J39: World Teachers’ Day — recognize HSF teachers through their actual work, not a generic greeting card. | K39: Planned | M39: 4:00–5:00 PM | N39: Core | O39: P11 | P39: Issue | Q39: Children Need More Than Attendance; They Need Safety and a Voice | R39: Standard | S39: Planned | U39: =IF(C39="Friday","Friday Off",IF(AND(K39="Published",S39="Published"),"Both Published",IF(OR(K39="Needs Reschedule",S39="Needs Reschedule"),"Needs Reschedule",IF(OR(K39="Published",S39="Published"),"Partially Published",IF(AND(K39="Scheduled",S39="Scheduled"),"Scheduled","Planned"))))) -> Planned | V39: Use current verified E4BL activity evidence. Protect children’s dignity and privacy; no unnecessary names, registers or personal details. Do not infer learning outcomes.
A40: 36 | B40: 46301 | C40: Tuesday | D40: Week 6 | E40: E4BL – Education | F40: Block 13 – Day 2 | G40: 9:00–10:00 AM | H40: MOMENT-015 | I40: MOMENT | J40: Teacher preparation or a safe classroom moment where children can participate and be heard. | K40: Planned | M40: 4:00–5:00 PM | N40: Core | O40: P12 | P40: Resolution | Q40: Safe Support Should Make It Easier for a Child to Be Heard | R40: Special Engagement | S40: Planned | U40: =IF(C40="Friday","Friday Off",IF(AND(K40="Published",S40="Published"),"Both Published",IF(OR(K40="Needs Reschedule",S40="Needs Reschedule"),"Needs Reschedule",IF(OR(K40="Published",S40="Published"),"Partially Published",IF(AND(K40="Scheduled",S40="Scheduled"),"Scheduled","Planned"))))) -> Planned | V40: Use current verified E4BL activity evidence. Protect children’s dignity and privacy; no unnecessary names, registers or personal details. Do not infer learning outcomes.
A41: 37 | B41: 46302 | C41: Wednesday | D41: Week 6 | E41: A2PHC – Health | F41: Block 14 – Day 1 | G41: 9:00–10:00 AM | H41: FIELD-019 | I41: FIELD | J41: A respectful A2PHC service moment showing access to care without stigma or pity-based framing. | K41: Planned | M41: 4:00–5:00 PM | N41: Core | O41: P31 | P41: Issue | Q41: Hardship Narrows Choices, but It Should Not Reduce Human Dignity | R41: Standard | S41: Planned | U41: =IF(C41="Friday","Friday Off",IF(AND(K41="Published",S41="Published"),"Both Published",IF(OR(K41="Needs Reschedule",S41="Needs Reschedule"),"Needs Reschedule",IF(OR(K41="Published",S41="Published"),"Partially Published",IF(AND(K41="Scheduled",S41="Scheduled"),"Scheduled","Planned"))))) -> Planned | V41: Use current verified A2PHC activity evidence. Protect patient privacy; no prescriptions, registers, diagnoses linked to people or unsupported clinical outcome claims. | W41: Cross-cutting core theme; keep the locked heading and express examples through this day’s programme lens.
...

Sheet Weekly Rhythm
A1: HSF Weekly Social Communication Rhythm
A2: Operational rhythm from 07 September 2026. The programme stays the same for morning and afternoon; each two-day block carries an Issue → Resolution pair.
A4: Day | B4: Programme | C4: Morning Stream | D4: Afternoon Stream | E4: Pair Role | F4: Posting Rule | G4: Purpose
A5: Monday | B5: E4BL – Education | C5: HSF in Action | D5: Core P-post | E5: Issue | F5: Publish if real/safe morning evidence exists | G5: Begin Education pair
A6: Tuesday | B6: E4BL – Education | C6: HSF in Action | D6: Core P-post | E6: Resolution | F6: Same programme all day | G6: Complete Education pair
A7: Wednesday | B7: A2PHC – Health | C7: HSF in Action | D7: Core P-post | E7: Issue | F7: Publish if real/safe morning evidence exists | G7: Begin Health pair
A8: Thursday | B8: A2PHC – Health | C8: HSF in Action | D8: Core P-post | E8: Resolution | F8: Same programme all day | G8: Complete Health pair
A9: Friday | B9: — | C9: NO POST | D9: NO POST | E9: — | F9: Full weekly pause | G9: Audience and production breathing room
A10: Saturday | B10: Climate Action | C10: HSF in Action | D10: Core P-post | E10: Issue | F10: Publish if real/safe morning evidence exists | G10: Begin Climate pair
A11: Sunday | B11: Climate Action | C11: HSF in Action | D11: Core P-post | E11: Resolution | F11: Same programme all day | G11: Complete Climate pair
A13: Operating Rules
A14: 1 | B14: Morning overlays are opportunity-led, not quota-led. If there is no genuine, safe and useful activity, the morning post may be skipped.
A15: 2 | B15: From 07 September onward, morning and afternoon must use the same programme lens.
A16: 3 | B16: P01–P48 IDs and headings remain locked. The schedule changes dates and programme framing, not the approved core content.
A17: 4 | B17: P31–P48 are cross-cutting themes; in this tracker they are expressed through the programme scheduled for that day without changing the locked heading.
A18: 5 | B18: Exact-date observances are used only when they fit the day’s programme. Otherwise the observance is skipped rather than breaking the rhythm.
A19: 6 | B19: Friday is a deliberate no-post day and is recorded in the tracker rather than omitted.
A20: 7 | B20: 01–06 September remain historical records. The new rhythm starts 07 September.

Sheet Dashboard
A1: HSF Social Communication Dashboard | As of 06 September 2026
A2: 48 locked core posts + morning HSF in Action overlays. Cycle ends 27 October 2026 because Fridays are intentionally off and 03 September carried an overlay-only afternoon.
A4: Core Posts | D4: Published Core | G4: Core Completion | I4: Published Posts
A5: =COUNTIF(Schedule!$N$5:$N$61,"Core") -> 48 | D5: =COUNTIFS(Schedule!$N$5:$N$61,"Core",Schedule!$S$5:$S$61,"Published") -> 4 | G5: =COUNTIFS(Schedule!$N$5:$N$61,"Core",Schedule!$S$5:$S$61,"Published")/COUNTIF(Schedule!$N$5:$N$61,"Core") -> 0.083333333 | I5: =COUNTIF(Schedule!$K$5:$K$61,"Published")+COUNTIF(Schedule!$S$5:$S$61,"Published") -> 10
A8: Scheduled Core | D8: Planned Core | G8: Published Morning | I8: Friday Off
A9: =COUNTIFS(Schedule!$N$5:$N$61,"Core",Schedule!$S$5:$S$61,"Scheduled") -> 4 | D9: =COUNTIFS(Schedule!$N$5:$N$61,"Core",Schedule!$S$5:$S$61,"Planned") -> 40 | G9: =COUNTIF(Schedule!$K$5:$K$61,"Published") -> 5 | I9: =COUNTIF(Schedule!$U$5:$U$61,"Friday Off") -> 8
A12: Core Status | D12: Core Coverage by Programme Lens | H12: Tracker Alerts
A13: Status | B13: Count | D13: Programme | E13: Total Core | F13: Published Core | H13: Item | I13: Count
A14: Published | B14: =COUNTIFS(Schedule!$N$5:$N$61,"Core",Schedule!$S$5:$S$61,A14) -> 4 | D14: E4BL – Education | E14: =COUNTIFS(Schedule!$E$5:$E$61,D14,Schedule!$N$5:$N$61,"Core") -> 18 | F14: =COUNTIFS(Schedule!$E$5:$E$61,D14,Schedule!$N$5:$N$61,"Core",Schedule!$S$5:$S$61,"Published") -> 2 | H14: Needs Reschedule | I14: =COUNTIF(Schedule!$K$5:$K$61,"Needs Reschedule") -> 2
A15: Scheduled | B15: =COUNTIFS(Schedule!$N$5:$N$61,"Core",Schedule!$S$5:$S$61,A15) -> 4 | D15: A2PHC – Health | E15: =COUNTIFS(Schedule!$E$5:$E$61,D15,Schedule!$N$5:$N$61,"Core") -> 16 | F15: =COUNTIFS(Schedule!$E$5:$E$61,D15,Schedule!$N$5:$N$61,"Core",Schedule!$S$5:$S$61,"Published") -> 2 | H15: Morning Planned | I15: =COUNTIF(Schedule!$K$5:$K$61,"Planned") -> 40
A16: Planned | B16: =COUNTIFS(Schedule!$N$5:$N$61,"Core",Schedule!$S$5:$S$61,A16) -> 40 | D16: Climate Action | E16: =COUNTIFS(Schedule!$E$5:$E$61,D16,Schedule!$N$5:$N$61,"Core") -> 14 | F16: =COUNTIFS(Schedule!$E$5:$E$61,D16,Schedule!$N$5:$N$61,"Core",Schedule!$S$5:$S$61,"Published") -> 0 | H16: Morning Skipped | I16: =COUNTIF(Schedule!$K$5:$K$61,"Skipped") -> 0
A17: Needs Reschedule | B17: =COUNTIFS(Schedule!$N$5:$N$61,"Core",Schedule!$S$5:$S$61,A17) -> 0
A19: Management Notes
A20: • 06 September is corrected to both posts published.
A21: • 09–10 September morning content requires rescheduling from Education to Health; afternoon P15/P16 remains scheduled.
A22: • Morning overlays are planned opportunities, not compulsory quotas. A weak or unsupported morning post should be skipped.
A23: • Dashboard counts update automatically when Morning Status or Afternoon Status is changed in the Schedule sheet.
